Workbook

Sheet Por Capítulo (2)
E3: 2024 | F3: 2025
E4: 855934344 | F4: 906482936 | G4: =F4-E4 -> 50548592
E5: 164480532 | F5: 76595744 | G5: =F5-E5 -> -87884788
E6: 400856497 | F6: 329849243 | G6: =F6-E6 -> -71007254

Sheet Por Capítulo

Sheet Por Partida
K4: O001 - Actividades de apoyo a la función pública y buen gobierno
E5: =C5/1000 -> 906482.94 | F5: 907214.8 | G5: =F5-E5 -> 731.864 | K5: Capítulo | L5: Ejercido
E6: =B6/1000 -> 21.101 | K6: 1000 - Servicios personales | L6: 5655091
E7: =B7/1000 -> 21.201 | K7: 3000 - Servicios generales | L7: 719436
E8: =B8/1000 -> 21.401 | K8: Total general | L8: 6374527
E9: =B9/1000 -> 21.501 | K9: Fuente: Cuenta Pública 2025
E10: =B10/1000 -> 21.502 | G10: =B10*1.0369 -> 22295.424
E11: =B11/1000 -> 21.601
E12: =B12/1000 -> 22.104
E13: =B13/1000 -> 22.201
E14: =B14/1000 -> 22.301
E15: =B15/1000 -> 24.101
E16: =B16/1000 -> 24.201
E17: =B17/1000 -> 24.601
E18: =B18/1000 -> 24.701
E19: =B19/1000 -> 24.801
E20: =B20/1000 -> 24.901
E21: =B21/1000 -> 25.101
E22: =B22/1000 -> 25.301
... E29: =B29/1000 -> 29.101

Sheet BASE AC01 2025
A1: Ramo | B1: Unidad | C1: Finalidad | D1: Funcion | E1: Subfuncion | F1: Reasignaciones | G1: Actividad Institucional | H1: PP | I1: Modalidad | J1: Programa | K1: Capítulo | L1: Partida | M1: Descripción partida | N1: Tipo de Gasto | O1: Fuente de Financiamiento | P1: Entidad Federativa | Q1: Clave de Cartera | R1: Original | S1: Modificado | T1: Devengado | U1: Ejercido | V1: Pagado
A2: 12 | B2: NDE | C2: 1 | D2: 3 | E2: 4 | F2: 0 | G2: 1 | H2: =I2&"00"&J2 -> O001 | I2: O | J2: 1 | K2: 1000 | L2: 11301 | M2: =VLOOKUP(L2,'Catálogos'!$A$2:$B$492,2,0) -> Sueldos base | N2: 1 | O2: 1 | P2: 9 | Q2: 0 | R2: 1782556 | S2: 1781281 | T2: 1781281 | U2: 1781281 | V2: 1781281
A3: 12 | B3: NDE | C3: 1 | D3: 3 | E3: 4 | F3: 0 | G3: 1 | H3: =I3&"00"&J3 -> O001 | I3: O | J3: 1 | K3: 1000 | L3: 13101 | M3: =VLOOKUP(L3,'Catálogos'!$A$2:$B$492,2,0) -> Prima quinquenal por años de servicios efectivos prestados | N3: 1 | O3: 1 | P3: 9 | Q3: 0 | R3: 41993 | S3: 41993 | T3: 41993 | U3: 41993 | V3: 41993
A4: 12 | B4: NDE | C4: 1 | D4: 3 | E4: 4 | F4: 0 | G4: 1 | H4: =I4&"00"&J4 -> O001 | I4: O | J4: 1 | K4: 1000 | L4: 13201 | M4: =VLOOKUP(L4,'Catálogos'!$A$2:$B$492,2,0) -> Primas de vacaciones y dominical | N4: 1 | O4: 1 | P4: 9 | Q4: 0 | R4: 74134 | S4: 74134 | T4: 74134 | U4: 74134 | V4: 74134
A5: 12 | B5: NDE | C5: 1 | D5: 3 | E5: 4 | F5: 0 | G5: 1 | H5: =I5&"00"&J5 -> O001 | I5: O | J5: 1 | K5: 1000 | L5: 13202 | M5: =VLOOKUP(L5,'Catálogos'!$A$2:$B$492,2,0) -> Aguinaldo o gratificación de fin de año | N5: 1 | O5: 1 | P5: 9 | Q5: 0 | R5: 237320 | S5: 253460 | T5: 253460 | U5: 253460 | V5: 253460
A6: 12 | B6: NDE | C6: 1 | D6: 3 | E6: 4 | F6: 0 | G6: 1 | H6: =I6&"00"&J6 -> O001 | I6: O | J6: 1 | K6: 1000 | L6: 13301 | M6: =VLOOKUP(L6,'Catálogos'!$A$2:$B$492,2,0) -> Remuneraciones por horas extraordinarias | N6: 1 | O6: 1 | P6: 9 | Q6: 0 | R6: 9132 | S6: 6400 | T6: 6400 | U6: 6400 | V6: 6400
A7: 12 | B7: NDE | C7: 1 | D7: 3 | E7: 4 | F7: 0 | G7: 1 | H7: =I7&"00"&J7 -> O001 | I7: O | J7: 1 | K7: 1000 | L7: 13404 | M7: =VLOOKUP(L7,'Catálogos'!$A$2:$B$492,2,0) -> Compensaciones por servicios eventuales | N7: 1 | O7: 1 | P7: 9 | Q7: 0 | R7: 23694 | S7: 26466 | T7: 26466 | U7: 26466 | V7: 26466
A8: 12 | B8: NDE | C8: 1 | D8: 3 | E8: 4 | F8: 0 | G8: 1 | H8: =I8&"00"&J8 -> O001 | I8: O | J8: 1 | K8: 1000 | L8: 13407 | M8: =VLOOKUP(L8,'Catálogos'!$A$2:$B$492,2,0) -> Compensaciones adicionales por servicios especiales | N8: 1 | O8: 1 | P8: 9 | Q8: 0 | R8: 190950 | S8: 190950 | T8: 190950 | U8: 190950 | V8: 190950
A9: 12 | B9: NDE | C9: 1 | D9: 3 | E9: 4 | F9: 0 | G9: 1 | H9: =I9&"00"&J9 -> O001 | I9: O | J9: 1 | K9: 1000 | L9: 13410 | M9: =VLOOKUP(L9,'Catálogos'!$A$2:$B$492,2,0) -> Compensación por actualización y formación académica | N9: 1 | O9: 1 | P9: 9 | Q9: 0 | R9: 720504 | S9: 712071 | T9: 712071 | U9: 712071 | V9: 712071
A10: 12 | B10: NDE | C10: 1 | D10: 3 | E10: 4 | F10: 0 | G10: 1 | H10: =I10&"00"&J10 -> O001 | I10: O | J10: 1 | K10: 1000 | L10: 14101 | M10: =VLOOKUP(L10,'Catálogos'!$A$2:$B$492,2,0) -> Aportaciones al ISSSTE | N10: 1 | O10: 1 | P10: 9 | Q10: 0 | R10: 560060 | S10: 443132 | T10: 443132 | U10: 443132 | V10: 443132
A11: 12 | B11: NDE | C11: 1 | D11: 3 | E11: 4 | F11: 0 | G11: 1 | H11: =I11&"00"&J11 -> O001 | I11: O | J11: 1 | K11: 1000 | L11: 14105 | M11: =VLOOKUP(L11,'Catálogos'!$A$2:$B$492,2,0) -> Aportaciones al seguro de cesantía en edad avanzada y vejez | N11: 1 | O11: 1 | P11: 9 | Q11: 0 | R11: 104739 | S11: 104739 | T11: 104739 | U11: 104739 | V11: 104739
A12: 12 | B12: NDE | C12: 1 | D12: 3 | E12: 4 | F12: 0 | G12: 1 | H12: =I12&"00"&J12 -> O001 | I12: O | J12: 1 | K12: 1000 | L12: 14201 | M12: =VLOOKUP(L12,'Catálogos'!$A$2:$B$492,2,0) -> Aportaciones al FOVISSSTE | N12: 1 | O12: 1 | P12: 9 | Q12: 0 | R12: 102548 | S12: 102548 | T12: 102548 | U12: 102548 | V12: 102548
A13: 12 | B13: NDE | C13: 1 | D13: 3 | E13: 4 | F13: 0 | G13: 1 | H13: =I13&"00"&J13 -> O001 | I13: O | J13: 1 | K13: 1000 | L13: 14301 | M13: =VLOOKUP(L13,'Catálogos'!$A$2:$B$492,2,0) -> Aportaciones al Sistema de Ahorro para el Retiro | N13: 1 | O13: 1 | P13: 9 | Q13: 0 | R13: 41019 | S13: 41019 | T13: 41019 | U13: 41019 | V13: 41019
... A41: 12 | B41: NDE | C41: 1 | D41: 3 | E41: 4 | F41: 0 | G41: 1 | H41: =I41&"00"&J41 -> O001 | I41: O | J41: 1 | K41: 3000 | L41: 39801 | M41: =VLOOKUP(L41,'Catálogos'!$A$2:$B$492,2,0) -> Impuesto sobre nóminas | N41: 1 | O41: 1 | P41: 9 | Q41: 0 | R41: 94643 | S41: 117524 | T41: 117524 | U41: 117524 | V41: 117524
A42: 12 | B42: NDE | C42: 2 | D42: 3 | E42: 2 | F42: 0 | G42: 18 | H42: =I42&"0"&J42 -> E023 | I42: E | J42: 23 | K42: 1000 | L42: 11301 | M42: =VLOOKUP(L42,'Catálogos'!$A$2:$B$492,2,0) -> Sueldos base | N42: 1 | O42: 1 | P42: 9 | Q42: 0 | R42: 167880258 | S42: 219176585 | T42: 219176585 | U42: 219176585 | V42: 219176585
A43: 12 | B43: NDE | C43: 2 | D43: 3 | E43: 2 | F43: 0 | G43: 18 | H43: =I43&"0"&J43 -> E023 | I43: E | J43: 23 | K43: 1000 | L43: 12201 | M43: =VLOOKUP(L43,'Catálogos'!$A$2:$B$492,2,0) -> Sueldos base al personal eventual | N43: 1 | O43: 1 | P43: 9 | Q43: 0 | R43: 0 | S43: 33484005 | T43: 33484005 | U43: 33484005 | V43: 33484005
A44: 12 | B44: NDE | C44: 2 | D44: 3 | E44: 2 | F44: 0 | G44: 18 | H44: =I44&"0"&J44 -> E023 | I44: E | J44: 23 | K44: 1000 | L44: 13101 | M44: =VLOOKUP(L44,'Catálogos'!$A$2:$B$492,2,0) -> Prima quinquenal por años de servicios efectivos prestados | N44: 1 | O44: 1 | P44: 9 | Q44: 0 | R44: 3954856 | S44: 4357776 | T44: 4357776 | U44: 4357776 | V44: 4357776
A45: 12 | B45: NDE | C45: 2 | D45: 3 | E45: 2 | F45: 0 | G45: 18 | H45: =I45&"0"&J45 -> E023 | I45: E | J45: 23 | K45: 1000 | L45: 13201 | M45: =VLOOKUP(L45,'Catálogos'!$A$2:$B$492,2,0) -> Primas de vacaciones y dominical | N45: 1 | O45: 1 | P45: 9 | Q45: 0 | R45: 6981832 | S45: 11570305 | T45: 11570305 | U45: 11570305 | V45: 11570305
A46: 12 | B46: NDE | C46: 2 | D46: 3 | E46: 2 | F46: 0 | G46: 18 | H46: =I46&"0"&J46 -> E023 | I46: E | J46: 23 | K46: 1000 | L46: 13202 | M46: =VLOOKUP(L46,'Catálogos'!$A$2:$B$492,2,0) -> Aguinaldo o gratificación de fin de año | N46: 1 | O46: 1 | P46: 9 | Q46: 0 | R46: 22350668 | S46: 29629732 | T46: 29629732 | U46: 29629732 | V46: 29629732
A47: 12 | B47: NDE | C47: 2 | D47: 3 | E47: 2 | F47: 0 | G47: 18 | H47: =I47&"0"&J47 -> E023 | I47: E | J47: 23 | K47: 1000 | L47: 13301 | M47: =VLOOKUP(L47,'Catálogos'!$A$2:$B$492,2,0) -> Remuneraciones por horas extraordinarias | N47: 1 | O47: 1 | P47: 9 | Q47: 0 | R47: 860050 | S47: 590820 | T47: 590820 | U47: 590820 | V47: 590820
A48: 12 | B48: NDE | C48: 2 | D48: 3 | E48: 2 | F48: 0 | G48: 18 | H48: =I48&"0"&J48 -> E023 | I48: E | J48: 23 | K48: 1000 | L48: 13404 | M48: =VLOOKUP(L48,'Catálogos'!$A$2:$B$492,2,0) -> Compensaciones por servicios eventuales | N48: 1 | O48: 1 | P48: 9 | Q48: 0 | R48: 2231429 | S48: 3678944 | T48: 3678944 | U48: 3678944 | V48: 3678944
A49: 12 | B49: NDE | C49: 2 | D49: 3 | E49: 2 | F49: 0 | G49: 18 | H49: =I49&"0"&J49 -> E023 | I49: E | J49: 23 | K49: 1000 | L49: 13407 | M49: =VLOOKUP(L49,'Catálogos'!$A$2:$B$492,2,0) -> Compensaciones adicionales por servicios especiales | N49: 1 | O49: 1 | P49: 9 | Q49: 0 | R49: 17983755 | S49: 21537902 | T49: 21537902 | U49: 21537902 | V49: 21537902
A50: 12 | B50: NDE | C50: 2 | D50: 3 | E50: 2 | F50: 0 | G50: 18 | H50: =I50&"0"&J50 -> E023 | I50: E | J50: 23 | K50: 1000 | L50: 13410 | M50: =VLOOKUP(L50,'Catálogos'!$A$2:$B$492,2,0) -> Compensación por actualización y formación académica | N50: 1 | O50: 1 | P50: 9 | Q50: 0 | R50: 67856808 | S50: 80683726 | T50: 80683726 | U50: 80683726 | V50: 80683726
A51: 12 | B51: NDE | C51: 2 | D51: 3 | E51: 2 | F51: 0 | G51: 18 | H51: =I51&"0"&J51 -> E023 | I51: E | J51: 23 | K51: 1000 | L51: 14101 | M51: =VLOOKUP(L51,'Catálogos'!$A$2:$B$492,2,0) -> Aportaciones al ISSSTE | N51: 1 | O51: 1 | P51: 9 | Q51: 0 | R51: 29352290 | S51: 24924648 | T51: 24924648 | U51: 24924648 | V51: 24924648
A52: 12 | B52: NDE | C52: 2 | D52: 3 | E52: 2 | F52: 0 | G52: 18 | H52: =I52&"0"&J52 -> E023 | I52: E | J52: 23 | K52: 1000 | L52: 14105 | M52: =VLOOKUP(L52,'Catálogos'!$A$2:$B$492,2,0) -> Aportaciones al seguro de cesantía en edad avanzada y vejez | N52: 1 | O52: 1 | P52: 9 | Q52: 0 | R52: 9864416 | S52: 8588088 | T52: 8588088 | U52: 8588088 | V52: 8588088
A53: 12 | B53: NDE | C53: 2 | D53: 3 | E53: 2 | F53: 0 | G53: 18 | H53: =I53&"0"&J53 -> E023 | I53: E | J53: 23 | K53: 1000 | L53: 14201 | M53: =VLOOKUP(L53,'Catálogos'!$A$2:$B$492,2,0) -> Aportaciones al FOVISSSTE | N53: 1 | O53: 1 | P53: 9 | Q53: 0 | R53: 9658008 | S53: 11040989 | T53: 11040989 | U53: 11040989 | V53: 11040989
... A208: 12 | B208: NDE | C208: 2 | D208: 3 | E208: 3 | F208: 0 | G208: 19 | H208: =I208&"0"&J208 -> E010 | I208: E | J208: 10 | K208: 3000 | L208: 39801 | M208: =VLOOKUP(L208,'Catálogos'!$A$2:$B$492,2,0) -> Impuesto sobre nóminas | N208: 1 | O208: 1 | P208: 9 | Q208: 0 | R208: 1175700 | S208: 1470226 | T208: 1470226 | U208: 1470226 | V208: 1470226
A209: 12 | B209: NDE | C209: 2 | D209: 3 | E209: 4 | F209: 0 | G209: 2 | H209: =I209&"00"&J209 -> M001 | I209: M | J209: 1 | K209: 1000 | L209: 11301 | M209: =VLOOKUP(L209,'Catálogos'!$A$2:$B$492,2,0) -> Sueldos base | N209: 1 | O209: 1 | P209: 9 | Q209: 0 | R209: 14803141 | S209: 14711608 | T209: 14711608 | U209: 14711608 | V209: 14711608
A210: 12 | B210: NDE | C210: 2 | D210: 3 | E210: 4 | F210: 0 | G210: 2 | H210: =I210&"00"&J210 -> M001 | I210: M | J210: 1 | K210: 1000 | L210: 12301 | M210: =VLOOKUP(L210,'Catálogos'!$A$2:$B$492,2,0) -> Retribuciones por servicios de carácter social | N210: 1 | O210: 1 | P210: 9 | Q210: 0 | R210: 0 | S210: 98237 | T210: 98237 | U210: 98237 | V210: 98237
A211: 12 | B211: NDE | C211: 2 | D211: 3 | E211: 4 | F211: 0 | G211: 2 | H211: =I211&"00"&J211 -> M001 | I211: M | J211: 1 | K211: 1000 | L211: 13101 | M211: =VLOOKUP(L211,'Catálogos'!$A$2:$B$492,2,0) -> Prima quinquenal por años de servicios efectivos prestados | N211: 1 | O211: 1 | P211: 9 | Q211: 0 | R211: 348729 | S211: 348729 | T211: 348729 | U211: 348729 | V211: 348729
A212: 12 | B212: NDE | C212: 2 | D212: 3 | E212: 4 | F212: 0 | G212: 2 | H212: =I212&"00"&J212 -> M001 | I212: M | J212: 1 | K212: 1000 | L212: 13201 | M212: =VLOOKUP(L212,'Catálogos'!$A$2:$B$492,2,0) -> Primas de vacaciones y dominical | N212: 1 | O212: 1 | P212: 9 | Q212: 0 | R212: 615635 | S212: 619756 | T212: 619756 | U212: 619756 | V212: 619756
A213: 12 | B213: NDE | C213: 2 | D213: 3 | E213: 4 | F213: 0 | G213: 2 | H213: =I213&"00"&J213 -> M001 | I213: M | J213: 1 | K213: 1000 | L213: 13202 | M213: =VLOOKUP(L213,'Catálogos'!$A$2:$B$492,2,0) -> Aguinaldo o gratificación de fin de año | N213: 1 | O213: 1 | P213: 9 | Q213: 0 | R213: 1970810 | S213: 2236743 | T213: 2236743 | U213: 2236743 | V213: 2236743
A214: 12 | B214: NDE | C214: 2 | D214: 3 | E214: 4 | F214: 0 | G214: 2 | H214: =I214&"00"&J214 -> M001 | I214: M | J214: 1 | K214: 1000 | L214: 13301 | M214: =VLOOKUP(L214,'Catálogos'!$A$2:$B$492,2,0) -> Remuneraciones por horas extraordinarias | N214: 1 | O214: 1 | P214: 9 | Q214: 0 | R214: 75836 | S214: 53135 | T214: 53135 | U214: 53135 | V214: 53135
A215: 12 | B215: NDE | C215: 2 | D215: 3 | E215: 4 | F215: 0 | G215: 2 | H215: =I215&"00"&J215 -> M001 | I215: M | J215: 1 | K215: 1000 | L215: 13404 | M215: =VLOOKUP(L215,'Catálogos'!$A$2:$B$492,2,0) -> Compensaciones por servicios eventuales | N215: 1 | O215: 1 | P215: 9 | Q215: 0 | R215: 196761 | S215: 303589 | T215: 303589 | U215: 303589 | V215: 303589
A216: 12 | B216: NDE | C216: 2 | D216: 3 | E216: 4 | F216: 0 | G216: 2 | H216: =I216&"00"&J216 -> M001 | I216: M | J216: 1 | K216: 1000 | L216: 13407 | M216: =VLOOKUP(L216,'Catálogos'!$A$2:$B$492,2,0) -> Compensaciones adicionales por servicios especiales | N216: 1 | O216: 1 | P216: 9 | Q216: 0 | R216: 1585751 | S216: 1605398 | T216: 1605398 | U216: 1605398 | V216: 1605398
A217: 12 | B217: NDE | C217: 2 | D217: 3 | E217: 4 | F217: 0 | G217: 2 | H217: =I217&"00"&J217 -> M001 | I217: M | J217: 1 | K217: 1000 | L217: 13410 | M217: =VLOOKUP(L217,'Catálogos'!$A$2:$B$492,2,0) -> Compensación por actualización y formación académica | N217: 1 | O217: 1 | P217: 9 | Q217: 0 | R217: 5983396 | S217: 5791524 | T217: 5791524 | U217: 5791524 | V217: 5791524
A218: 12 | B218: NDE | C218: 2 | D218: 3 | E218: 4 | F218: 0 | G218: 2 | H218: =I218&"00"&J218 -> M001 | I218: M | J218: 1 | K218: 1000 | L218: 13411 | M218: =VLOOKUP(L218,'Catálogos'!$A$2:$B$492,2,0) -> Compensaciones a médicos residentes | N218: 1 | O218: 1 | P218: 9 | Q218: 0 | R218: 0 | S218: 124831 | T218: 124831 | U218: 124831 | V218: 124831
A219: 12 | B219: NDE | C219: 2 | D219: 3 | E219: 4 | F219: 0 | G219: 2 | H219: =I219&"00"&J219 -> M001 | I219: M | J219: 1 | K219: 1000 | L219: 14101 | M219: =VLOOKUP(L219,'Catálogos'!$A$2:$B$492,2,0) -> Aportaciones al ISSSTE | N219: 1 | O219: 1 | P219: 9 | Q219: 0 | R219: 4650977 | S219: 3533881 | T219: 3533881 | U219: 3533881 | V219: 3533881
A220: 12 | B220: NDE | C220: 2 | D220: 3 | E220: 4 | F220: 0 | G220: 2 | H220: =I220&"00"&J220 -> M001 | I220: M | J220: 1 | K220: 1000 | L220: 14105 | M220: =VLOOKUP(L220,'Catálogos'!$A$2:$B$492,2,0) -> Aportaciones al seguro de cesantía en edad avanzada y vejez | N220: 1 | O220: 1 | P220: 9 | Q220: 0 | R220: 869813 | S220: 873556 | T220: 873556 | U220: 873556 | V220: 873556
... A274: 12 | B274: NDE | C274: 2 | D274: 3 | E274: 4 | F274: 0 | G274: 2 | H274: =I274&"00"&J274 -> M001 | I274: M | J274: 1 | K274: 3000 | L274: 39801 | M274: =VLOOKUP(L274,'Catálogos'!$A$2:$B$492,2,0) -> Impuesto sobre nóminas | N274: 1 | O274: 1 | P274: 9 | Q274: 0 | R274: 1365474 | S274: 10404058 | T274: 10404058 | U274: 10404058 | V274: 10404058
...

Sheet Hoja1
A1: MONTOS DE LA PARTIDA 35201 REPORTADOS EN CUENTA PUBLICA 2025
A2: Ramo | B2: Unidad | C2: Finalidad | D2: Funcion | E2: Subfuncion | F2: Reasignaciones | G2: Actividad Institucional | H2: Modalidad | I2: Programa | J2: Capítulo | K2: Partida | L2: Tipo de Gasto | M2: Fuente de Financiamiento | N2: Entidad Federativa | O2: Clave de Cartera | P2: Original | Q2: Modificado | R2: Devengado | S2: Ejercido | T2: Pagado
A3: 12 | B3: NDE | C3: 2 | D3: 3 | E3: 2 | F3: 0 | G3: 18 | H3: E | I3: 23 | J3: 3000 | K3: 35201 | L3: 1 | M3: 1 | N3: 9 | O3: 0 | P3: 408282 | Q3: 885859 | R3: 885859 | S3: 885859 | T3: 885859
A4: 12 | B4: NDE | C4: 2 | D4: 3 | E4: 4 | F4: 0 | G4: 2 | H4: M | I4: 1 | J4: 3000 | K4: 35201 | L4: 1 | M4: 1 | N4: 9 | O4: 0 | P4: 0 | Q4: 147292 | R4: 147292 | S4: 147292 | T4: 147292
A5: 12 | B5: NDE | C5: 3 | D5: 8 | E5: 1 | F5: 0 | G5: 24 | H5: E | I5: 22 | J5: 3000 | K5: 35201 | L5: 1 | M5: 1 | N5: 9 | O5: 0 | P5: 398913 | Q5: 716783 | R5: 716783 | S5: 716783 | T5: 716783
A6: 12 | B6: NDE | C6: 2 | D6: 3 | E6: 2 | F6: 0 | G6: 18 | H6: E | I6: 23 | J6: 3000 | K6: 35201 | L6: 1 | M6: 4 | N6: 9 | O6: 0 | P6: 52000 | Q6: 52000 | R6: 7150 | S6: 7150 | T6: 7150
A7: 12 | B7: NDE | C7: 3 | D7: 8 | E7: 1 | F7: 0 | G7: 24 | H7: E | I7: 22 | J7: 3000 | K7: 35201 | L7: 1 | M7: 4 | N7: 9 | O7: 0 | P7: 52000 | Q7: 0 | R7: 0 | S7: 0 | T7: 0
P8: =SUM(P3:P7) -> 911195 | Q8: =SUM(Q3:Q7) -> 1801934 | R8: =SUM(R3:R7) -> 1757084 | S8: =SUM(S3:S7) -> 1757084 | T8: =SUM(T3:T7) -> 1757084
T9: *Montos tomados del archivo AC01presntado en Cuenta Pública 2025

Sheet Catálogos
A1: Partida Específica | B1: Descripción
A2: 11101 | B2: Dietas
A3: 11201 | B3: Haberes
A4: 11301 | B4: Sueldos base
A5: 11401 | B5: Retribuciones por adscripción en el extranjero
A6: 12101 | B6: Honorarios
A7: 12201 | B7: Sueldos base al personal eventual
A8: 12202 | B8: Compensaciones a sustitutos de profesores
A9: 12301 | B9: Retribuciones por servicios de carácter social
A10: 12401 | B10: Retribución a los representantes de los trabajadores y de los patrones en la Junta Federal de Conciliación y Arbitraje
A11: 13101 | B11: Prima quinquenal por años de servicios efectivos prestados
A12: 13102 | B12: Acreditación por años de servicio en la docencia y al personal administrativo de las instituciones de educación superior
A13: 13103 | B13: Prima de perseverancia por años de servicio activo en el Ejército, Fuerza Aérea y Armada Mexicanos
... A492: 99101 | B492: Adeudos de ejercicios fiscales anteriores
